Workbook

Sheet Comments
A1: PLEASE NOTICE: The information in this spreadsheet could be revised and improved as new sources of information become available. To get the latest version of the spreadsheet, please contact M. Lucrecia Pettinari at mlucrecia.pettinari@uah.es
A3: CHANGES FROM PREVIOUS VERSION
A4: Version 1.1 | B4: Error detected in the convernsion factors from English to Metric units. Errors detected in some references. Solution:
A5: 1 | B5: The parameters W_1h, W_10h, W_100h and W_1000h loads in the Fuelbeds_metric sheet were corrected, because the previous version had used the wrong facto to convert from English units
A6: 2 | B6: Several references were corrected in the References sheet:
C7: 5091a, 5091b, 5091c, 8091a, 8091b
C8: 8091a, 8091b, 4092a, 4092b, 4092c, 4112a, 4112b, 4102, 4122a, 4122b, 5092a, 5092b, 5112, 5122, 6092a, 6092b, 6092c, 6102a, 6102b, 6112a, 6112b, 6122a, 6122b, 8092a, 8092b, 8112, 8122, 11092a, 11092b, 11102, 11112, 11122
C9: 5100a, 5100b, 5100c, 5110a, 5110b, 5120, 8100a, 8100b, 8110b, 5020, 5022, 5030, 5032, 5033, 5035
C10: 4100a, 4100b, 4100c, 4110a, 4110b, 4120a, 4120b
C11: 8030, 8032, 8033, 8035, 8038, 8039
C12: 4040a, 4040b, 4040c, 4061a, 4061b, 4061c, 5040, 5061a, 5061b, 5061c, 8040, 8061a, 8061b, 4020, 4030a, 4030b, 4021, 4031a, 4031b, 4022, 4032, 4023, 4033, 4027, 4037, 4028
A14: Version 1.2 | B14: Update of codes for Canopy Ladder Type used in FCCS
A15: 1 | B15: The codes for the Canopy Ladder Type parameter (T_LadderType) have been updated in the sheet "Definitions"
A16: 2 | B16: These codes have also been updated in column "T_LadderType" (column X) in the sheets "Fuelbeds_metric" and "Fuelbeds_english".
A21: COMMENTS ON THE TABLE
A22: The pages included in this file are:
B23: 1. Comments: this page, that includes important information to understand the data.
B24: 2. Definitions: Definition of each fuelbed variable, units and conversion factors.
B25: 3. Fuelbeds_metric: It contains all the fuelbeds, with their assigned variables, and with metric units.
B26: 4. Fuelbeds_english: It contains the same information on the fuelbeds than the previous page, but in English units, as it is the format required to input the data in FCCS.
B27: 5. References: Origin of the data used for or the variables assigned to each fuelbed
A29: Assumptions:
A30: FCCS includes several parameters within each fuelbed, that due to the generalization of the characteristics of the fuelbeds were left blank or assigned default values.
A31: These are:
A32: - Canopy:
B33: 1. Only Overstory and Midstory data were input, understory was left blank.
B34: 4. No Snag data were input.
A35: - Shrubs:
B36: 1. Only Primary Layer data were input, the secondary layer was left blank.
B37: 2. The "Is needle drape sufficient to affect fire behavior" option was set to NO by default.
A38: - Nonwoody fuels:
B39: 1. Only Primary Layer data were input, the secondary layer was left blank.
A40: - Woody fuels:
B41: 1. The "9-20 inches diameter" (10_000hrload) and "> 20 inches diameter" (>10_000hrload) woody fuels were left blank.
B42: 2. Rotten woody fuels, stump fuels and piles were left blank.
A43: - Ground fuels:
B44: 1. Basal Accumulation and Squirrel Middens are set as not present

Sheet Definitions
A1: Definition of each column in the following pages.
A3: VARIABLE | B3: DEFINITION | C3: UNITS IN METRIC SYSTEM | D3: UNITS IN ENGLISH SYSTEM | G3: Conversion factors
A4: N | B4: Correlative number for the purpose of ordering the data
A5: FUELBED | B5: Number of the Fuelbed | G5: 1 ft = 0.3048 m
A6: JOIN_VALUE | B6: Number of each fuelbed used to join the data to the Fuelbed Map | G6: 1 #/acre = 2.471 #/ha | H6: (1 acre = 0.4047 ha)
A7: Biome | B7: Corresponding Olson Biome | G7: 1 in = 2.54 cm
A8: LandCover | B8: Corresponding GlobCover landcover | G8: 1 T/acre = 2.242 Mg/ha | H8: (T=ton: US short ton, 0,907 Mg)
A9: Tree Cover | B9: Total percent cover of the tree stratum | C9: % | D9: %
A10: TO_Cover | B10: Overstory tree stratum percent cover | C10: % | D10: %
A11: TO_Density | B11: Overstory tree density | C11: #/ha | D11: #/acre
A12: TO_Height | B12: Overstory tree height | C12: m | D12: ft
A13: TO_HLC | B13: Overstory height to live crown | C13: m | D13: ft
A14: TO_DBH | B14: Overstory diameter at breast height | C14: cm | D14: in
A15: TO_SppNum | B15: Overstory species number (from the Inferred Variables Database inside FCCS v3.0)
A16: TO_SppName | B16: Overstory species name (from the Inferred Variables Database inside FCCS v3.0)
A17: TO_RelCover | B17: Overstory species relative cover | C17: % | D17: %
A18: TM_Cover | B18: Midstory tree stratum percent cover | C18: % | D18: %
A19: TM_Density | B19: Midstory tree density | C19: #/ha | D19: #/acre
A20: TM_Height | B20: Midstory tree height | C20: m | D20: ft
A21: TM_HLC | B21: Midstory height to live crown | C21: m | D21: ft
A22: TM_DBH | B22: Midstory diameter at breast height | C22: cm | D22: in
A23: TM_SppNum | B23: Midstory species number (from the Inferred Variables Database inside FCCS v3.0)
A24: TM_SppName | B24: Midstory species name (from the Inferred Variables Database inside FCCS v3.0)
A25: TM_RelCover | B25: Midstory species relative cover | C25: % | D25: %
A26: T_Ladder | B26: Ladder fuel presence (see below for possible values)
A27: T_LadderType | B27: Ladder fuel type (see below for possible values)
A28: Shrub Cover | B28: Primary shrub, percent cover | C28: % | D28: %
A29: S_Height | B29: Primary shrub, height | C29: m | D29: ft
A30: S_Live | B30: Primary shrub, percent live | C30: % | D30: %
A31: S_SppNum | B31: Primary shrub, species number (from the Inferred Variables Database inside FCCS v3.0)
A32: S_SppName | B32: Primary shrub, species name (from the Inferred Variables Database inside FCCS v3.0)
A33: S_RelCover | B33: Primary shrub species relative cover | C33: % | D33: %
A34: Grass Cover | B34: Primary nonwoody, percent cover | C34: % | D34: %
A35: G_height | B35: Primary nonwoody, height | C35: m | D35: ft
A36: G_live | B36: Primary nonwoody, percent live | C36: % | D36: %
A37: G_Load | B37: Primary nonwoody load | C37: Mg/ha | D37: ton/acre
A38: G_SppNum | B38: Primary nonwoody, species number (from the Inferred Variables Database inside FCCS v3.0)
A39: G_SppName | B39: Primary nonwoody, species name (from the Inferred Variables Database inside FCCS v3.0)
A40: G_RelCov | B40: Primary nonwoody species relative cover | C40: % | D40: %
A41: Woody Cover | B41: All downed wood, percent cover | C41: % | D41: %
...

Sheet Fuelbeds_metric
A1: N | B1: FUELBED | C1: JOIN_VALUE | D1: Biome | E1: LandCover | F1: Tree Cover (%) | G1: TO_Cover (%) | H1: TO_Density (#/ha) | I1: TO_Height (m) | J1: TO_HLC (m) | K1: TO_DBH (cm) | L1: TO_SppNum | M1: TO_SppName | N1: TO_RelCover (%) | O1: TM_Cover (%) | P1: TM_Density (#/ha) | Q1: TM_Height (m) | R1: TM_HLC (m) | S1: TM_DBH (cm) | T1: TM_SppNum | U1: TM_SppName | V1: TM_RelCover (%) | W1: T_Ladder | X1: T_LadderType | Y1: Shrub Cover (%) | Z1: S_Height (m) | AA1: S_Live (%) | AB1: S_SppNum | AC1: S_SppName | AD1: S_RelCover (%) | AE1: Grass Cover (%) | AF1: G_height (m) | AG1: G_live (%) | AH1: G_Load (Mg/ha) | AI1: G_SppNum | AJ1: G_SppName | AK1: G_RelCov (%) | AL1: Woody Cover (%) | AM1: W_depth (cm) | AN1: W_1hLoad (Mg/ha) | AO1: W_10h Load (Mg/ha) | AP1: W_100h Load (Mg/ha) | AQ1: W_1000h Load (Mg/ha) | AR1: W_SppNum | AS1: W_SppName | AT1: W_RelCov (%) | AU1: Lichen_Cover (%) | AV1: Lichen_Depth (cm) | AW1: Moss_Type | AX1: Moss_Cover (%) | AY1: Moss_Depth (cm) | AZ1: Litter_Arr | BA1: Litter_Cover (%) | BB1: L_depth (cm) | BC1: L_SNP_RelCov (%) | BD1: L_LNP_RelCov (%) | BE1: L_OC_RelCov (%) | BF1: L_BD_RelCov (%) | BG1: L_BE_RelCov (%) | BH1: L_PF_RelCov (%) | BI1: L_G_RelCov (%) | BJ1: DU_Type | BK1: DU_cover (%) | BL1: DU_Depth (in) | BM1: DL_Type | BN1: DL_cover (%) | BO1: DL_Depth (in)
A2: 1 | B2: 1010 | C2: 1010 | D2: 1 - Trop/Sub Moist Broadleaf Forest | E2: 10 - Crops: wheat, barley, sorgum | F2: -3 | G2: -3 | H2: =+IF(F2>0,INT(Fuelbeds_english!H2*2.471),F2) -> -3 | I2: =+IF(F2>0,INT(Fuelbeds_english!I2*0.3048),F2) -> -3 | J2: =+IF(F2>0,INT(Fuelbeds_english!J2*0.3048),F2) -> -3 | K2: =+IF(F2>0,INT(Fuelbeds_english!K2*2.54),F2) -> -3 | L2: -3 | M2: -3 | N2: -3 | O2: -3 | P2: =+IF(O2>0,INT(Fuelbeds_english!P2*2.471),O2) -> -3 | Q2: =+IF(O2>0,INT(Fuelbeds_english!Q2*0.3048),O2) -> -3 | R2: =+IF(O2>0,INT(Fuelbeds_english!R2*0.3048),O2) -> -3 | S2: =+IF(O2>0,INT(Fuelbeds_english!S2*2.54),O2) -> -3 | T2: -3 | U2: -3 | V2: -3 | W2: -3 | X2: -3 | Y2: -3 | Z2: =+IF(Y2>0,FIXED(Fuelbeds_english!Z2*0.3048,1,0),Y2) -> -3 | AA2: -3 | AB2: -3 | AC2: -3 | AD2: -3 | AE2: 100 | AF2: =+IF(AE2>0,FIXED(Fuelbeds_english!AF2*0.3048,1,0),AE2) -> 0.2 | AG2: 0 | AH2: =+IF(AE2>0,FIXED(Fuelbeds_english!AH2*2.242,1,0),AE2) -> 0.4 | AI2: 42236 | AJ2: Triticum spp. | AK2: 100 | AL2: -3 | AM2: =+IF(AL2>0,FIXED(Fuelbeds_english!AM2*2.54,1,0),AL2) -> -3 | AN2: =+IF(AM2>0,FIXED(Fuelbeds_english!AN2*0.3048,1,0),AM2) -> -3 | AO2: =+IF(AN2>0,FIXED(Fuelbeds_english!AO2*0.3048,1,0),AN2) -> -3 | AP2: =+IF(AO2>0,FIXED(Fuelbeds_english!AP2*0.3048,1,0),AO2) -> -3 | AQ2: =+IF(AP2>0,FIXED(Fuelbeds_english!AQ2*0.3048,1,0),AP2) -> -3 | AR2: -3 | AS2: -3 | AT2: -3 | AU2: -1 | AV2: =+IF(AU2>0,FIXED(Fuelbeds_english!AV2*2.54,1,0),AU2) -> -1 | AW2: -1 | AX2: -1 | AY2: =+IF(AX2>0,FIXED(Fuelbeds_english!AY2*2.54,1,0),AX2) -> -1 | AZ2: 2 | BA2: 65 | BB2: =+IF(BA2>0,FIXED(Fuelbeds_english!BB2*2.54,1,0),BA2) -> 1.3 | BC2: -1 | BD2: -1 | BE2: -1 | BF2: -1 | BG2: -1 | BH2: -1 | BI2: 100 | BJ2: -1 | BK2: -1 | BL2: =+IF(BK2>0,FIXED(Fuelbeds_english!BL2*2.54,1,0),BK2) -> -1 | BM2: -1 | BN2: -1 | BO2: =+IF(BN2>0,FIXED(Fuelbeds_english!BO2*2.54,1,0),BN2) -> -1
A3: 2 | B3: 1011 | C3: 1011 | D3: 1 - Trop/Sub Moist Broadleaf Forest | E3: 11 - Crops: rice | F3: -3 | G3: -3 | H3: =+IF(F3>0,INT(Fuelbeds_english!H3*2.471),F3) -> -3 | I3: =+IF(F3>0,INT(Fuelbeds_english!I3*0.3048),F3) -> -3 | J3: =+IF(F3>0,INT(Fuelbeds_english!J3*0.3048),F3) -> -3 | K3: =+IF(F3>0,INT(Fuelbeds_english!K3*2.54),F3) -> -3 | L3: -3 | M3: -3 | N3: -3 | O3: -3 | P3: =+IF(O3>0,INT(Fuelbeds_english!P3*2.471),O3) -> -3 | Q3: =+IF(O3>0,INT(Fuelbeds_english!Q3*0.3048),O3) -> -3 | R3: =+IF(O3>0,INT(Fuelbeds_english!R3*0.3048),O3) -> -3 | S3: =+IF(O3>0,INT(Fuelbeds_english!S3*2.54),O3) -> -3 | T3: -3 | U3: -3 | V3: -3 | W3: -3 | X3: -3 | Y3: -3 | Z3: =+IF(Y3>0,FIXED(Fuelbeds_english!Z3*0.3048,1,0),Y3) -> -3 | AA3: -3 | AB3: -3 | AC3: -3 | AD3: -3 | AE3: 100 | AF3: =+IF(AE3>0,FIXED(Fuelbeds_english!AF3*0.3048,1,0),AE3) -> 0.2 | AG3: 0 | AH3: =+IF(AE3>0,FIXED(Fuelbeds_english!AH3*2.242,1,0),AE3) -> 2.9 | AI3: 41976 | AJ3: Oryza sativa | AK3: 100 | AL3: -3 | AM3: =+IF(AL3>0,FIXED(Fuelbeds_english!AM3*2.54,1,0),AL3) -> -3 | AN3: =+IF(AM3>0,FIXED(Fuelbeds_english!AN3*0.3048,1,0),AM3) -> -3 | AO3: =+IF(AN3>0,FIXED(Fuelbeds_english!AO3*0.3048,1,0),AN3) -> -3 | AP3: =+IF(AO3>0,FIXED(Fuelbeds_english!AP3*0.3048,1,0),AO3) -> -3 | AQ3: =+IF(AP3>0,FIXED(Fuelbeds_english!AQ3*0.3048,1,0),AP3) -> -3 | AR3: -3 | AS3: -3 | AT3: -3 | AU3: -1 | AV3: =+IF(AU3>0,FIXED(Fuelbeds_english!AV3*2.54,1,0),AU3) -> -1 | AW3: -1 | AX3: -1 | AY3: =+IF(AX3>0,FIXED(Fuelbeds_english!AY3*2.54,1,0),AX3) -> -1 | AZ3: 2 | BA3: 65 | BB3: =+IF(BA3>0,FIXED(Fuelbeds_english!BB3*2.54,1,0),BA3) -> 1.3 | BC3: -1 | BD3: -1 | BE3: -1 | BF3: -1 | BG3: -1 | BH3: -1 | BI3: 100 | BJ3: -1 | BK3: -1 | BL3: =+IF(BK3>0,FIXED(Fuelbeds_english!BL3*2.54,1,0),BK3) -> -1 | BM3: -1 | BN3: -1 | BO3: =+IF(BN3>0,FIXED(Fuelbeds_english!BO3*2.54,1,0),BN3) -> -1
A4: 3 | B4: 1012 | C4: 1012 | D4: 1 - Trop/Sub Moist Broadleaf Forest | E4: 12 - Crops: maize | F4: -3 | G4: -3 | H4: =+IF(F4>0,INT(Fuelbeds_english!H4*2.471),F4) -> -3 | I4: =+IF(F4>0,INT(Fuelbeds_english!I4*0.3048),F4) -> -3 | J4: =+IF(F4>0,INT(Fuelbeds_english!J4*0.3048),F4) -> -3 | K4: =+IF(F4>0,INT(Fuelbeds_english!K4*2.54),F4) -> -3 | L4: -3 | M4: -3 | N4: -3 | O4: -3 | P4: =+IF(O4>0,INT(Fuelbeds_english!P4*2.471),O4) -> -3 | Q4: =+IF(O4>0,INT(Fuelbeds_english!Q4*0.3048),O4) -> -3 | R4: =+IF(O4>0,INT(Fuelbeds_english!R4*0.3048),O4) -> -3 | S4: =+IF(O4>0,INT(Fuelbeds_english!S4*2.54),O4) -> -3 | T4: -3 | U4: -3 | V4: -3 | W4: -3 | X4: -3 | Y4: -3 | Z4: =+IF(Y4>0,FIXED(Fuelbeds_english!Z4*0.3048,1,0),Y4) -> -3 | AA4: -3 | AB4: -3 | AC4: -3 | AD4: -3 | AE4: 100 | AF4: =+IF(AE4>0,FIXED(Fuelbeds_english!AF4*0.3048,1,0),AE4) -> 0.2 | AG4: 0 | AH4: =+IF(AE4>0,FIXED(Fuelbeds_english!AH4*2.242,1,0),AE4) -> 1.1 | AI4: 42269 | AJ4: Zea mays | AK4: 100 | AL4: -3 | AM4: =+IF(AL4>0,FIXED(Fuelbeds_english!AM4*2.54,1,0),AL4) -> -3 | AN4: =+IF(AM4>0,FIXED(Fuelbeds_english!AN4*0.3048,1,0),AM4) -> -3 | AO4: =+IF(AN4>0,FIXED(Fuelbeds_english!AO4*0.3048,1,0),AN4) -> -3 | AP4: =+IF(AO4>0,FIXED(Fuelbeds_english!AP4*0.3048,1,0),AO4) -> -3 | AQ4: =+IF(AP4>0,FIXED(Fuelbeds_english!AQ4*0.3048,1,0),AP4) -> -3 | AR4: -3 | AS4: -3 | AT4: -3 | AU4: -1 | AV4: =+IF(AU4>0,FIXED(Fuelbeds_english!AV4*2.54,1,0),AU4) -> -1 | AW4: -1 | AX4: -1 | AY4: =+IF(AX4>0,FIXED(Fuelbeds_english!AY4*2.54,1,0),AX4) -> -1 | AZ4: 2 | BA4: 65 | BB4: =+IF(BA4>0,FIXED(Fuelbeds_english!BB4*2.54,1,0),BA4) -> 1.3 | BC4: -1 | BD4: -1 | BE4: -1 | BF4: -1 | BG4: -1 | BH4: -1 | BI4: 100 | BJ4: -1 | BK4: -1 | BL4: =+IF(BK4>0,FIXED(Fuelbeds_english!BL4*2.54,1,0),BK4) -> -1 | BM4: -1 | BN4: -1 | BO4: =+IF(BN4>0,FIXED(Fuelbeds_english!BO4*2.54,1,0),BN4) -> -1
A5: 4 | B5: 1013 | C5: 1013 | D5: 1 - Trop/Sub Moist Broadleaf Forest | E5: 13 - Crops: Soybean | F5: -3 | G5: -3 | H5: =+IF(F5>0,INT(Fuelbeds_english!H5*2.471),F5) -> -3 | I5: =+IF(F5>0,INT(Fuelbeds_english!I5*0.3048),F5) -> -3 | J5: =+IF(F5>0,INT(Fuelbeds_english!J5*0.3048),F5) -> -3 | K5: =+IF(F5>0,INT(Fuelbeds_english!K5*2.54),F5) -> -3 | L5: -3 | M5: -3 | N5: -3 | O5: -3 | P5: =+IF(O5>0,INT(Fuelbeds_english!P5*2.471),O5) -> -3 | Q5: =+IF(O5>0,INT(Fuelbeds_english!Q5*0.3048),O5) -> -3 | R5: =+IF(O5>0,INT(Fuelbeds_english!R5*0.3048),O5) -> -3 | S5: =+IF(O5>0,INT(Fuelbeds_english!S5*2.54),O5) -> -3 | T5: -3 | U5: -3 | V5: -3 | W5: -3 | X5: -3 | Y5: -3 | Z5: =+IF(Y5>0,FIXED(Fuelbeds_english!Z5*0.3048,1,0),Y5) -> -3 | AA5: -3 | AB5: -3 | AC5: -3 | AD5: -3 | AE5: 100 | AF5: =+IF(AE5>0,FIXED(Fuelbeds_english!AF5*0.3048,1,0),AE5) -> 0.2 | AG5: 0 | AH5: =+IF(AE5>0,FIXED(Fuelbeds_english!AH5*2.242,1,0),AE5) -> 0.4 | AI5: 26716 | AJ5: Glycine max | AK5: 100 | AL5: -3 | AM5: =+IF(AL5>0,FIXED(Fuelbeds_english!AM5*2.54,1,0),AL5) -> -3 | AN5: =+IF(AM5>0,FIXED(Fuelbeds_english!AN5*0.3048,1,0),AM5) -> -3 | AO5: =+IF(AN5>0,FIXED(Fuelbeds_english!AO5*0.3048,1,0),AN5) -> -3 | AP5: =+IF(AO5>0,FIXED(Fuelbeds_english!AP5*0.3048,1,0),AO5) -> -3 | AQ5: =+IF(AP5>0,FIXED(Fuelbeds_english!AQ5*0.3048,1,0),AP5) -> -3 | AR5: -3 | AS5: -3 | AT5: -3 | AU5: -1 | AV5: =+IF(AU5>0,FIXED(Fuelbeds_english!AV5*2.54,1,0),AU5) -> -1 | AW5: -1 | AX5: -1 | AY5: =+IF(AX5>0,FIXED(Fuelbeds_english!AY5*2.54,1,0),AX5) -> -1 | AZ5: 2 | BA5: 65 | BB5: =+IF(BA5>0,FIXED(Fuelbeds_english!BB5*2.54,1,0),BA5) -> 1.3 | BC5: -1 | BD5: -1 | BE5: -1 | BF5: -1 | BG5: -1 | BH5: -1 | BI5: 100 | BJ5: -1 | BK5: -1 | BL5: =+IF(BK5>0,FIXED(Fuelbeds_english!BL5*2.54,1,0),BK5) -> -1 | BM5: -1 | BN5: -1 | BO5: =+IF(BN5>0,FIXED(Fuelbeds_english!BO5*2.54,1,0),BN5) -> -1
A6: 5 | B6: 1016 | C6: 1016 | D6: 1 - Trop/Sub Moist Broadleaf Forest | E6: 16 - Crops: beans | F6: -3 | G6: -3 | H6: =+IF(F6>0,INT(Fuelbeds_english!H6*2.471),F6) -> -3 | I6: =+IF(F6>0,INT(Fuelbeds_english!I6*0.3048),F6) -> -3 | J6: =+IF(F6>0,INT(Fuelbeds_english!J6*0.3048),F6) -> -3 | K6: =+IF(F6>0,INT(Fuelbeds_english!K6*2.54),F6) -> -3 | L6: -3 | M6: -3 | N6: -3 | O6: -3 | P6: =+IF(O6>0,INT(Fuelbeds_english!P6*2.471),O6) -> -3 | Q6: =+IF(O6>0,INT(Fuelbeds_english!Q6*0.3048),O6) -> -3 | R6: =+IF(O6>0,INT(Fuelbeds_english!R6*0.3048),O6) -> -3 | S6: =+IF(O6>0,INT(Fuelbeds_english!S6*2.54),O6) -> -3 | T6: -3 | U6: -3 | V6: -3 | W6: -3 | X6: -3 | Y6: -3 | Z6: =+IF(Y6>0,FIXED(Fuelbeds_english!Z6*0.3048,1,0),Y6) -> -3 | AA6: -3 | AB6: -3 | AC6: -3 | AD6: -3 | AE6: 100 | AF6: =+IF(AE6>0,FIXED(Fuelbeds_english!AF6*0.3048,1,0),AE6) -> 0.1 | AG6: 0 | AH6: =+IF(AE6>0,FIXED(Fuelbeds_english!AH6*2.242,1,0),AE6) -> 0.4 | AI6: 26857 | AJ6: Phaseolus vulgaris | AK6: 100 | AL6: -3 | AM6: =+IF(AL6>0,FIXED(Fuelbeds_english!AM6*2.54,1,0),AL6) -> -3 | AN6: =+IF(AM6>0,FIXED(Fuelbeds_english!AN6*0.3048,1,0),AM6) -> -3 | AO6: =+IF(AN6>0,FIXED(Fuelbeds_english!AO6*0.3048,1,0),AN6) -> -3 | AP6: =+IF(AO6>0,FIXED(Fuelbeds_english!AP6*0.3048,1,0),AO6) -> -3 | AQ6: =+IF(AP6>0,FIXED(Fuelbeds_english!AQ6*0.3048,1,0),AP6) -> -3 | AR6: -3 | AS6: -3 | AT6: -3 | AU6: -1 | AV6: =+IF(AU6>0,FIXED(Fuelbeds_english!AV6*2.54,1,0),AU6) -> -1 | AW6: -1 | AX6: -1 | AY6: =+IF(AX6>0,FIXED(Fuelbeds_english!AY6*2.54,1,0),AX6) -> -1 | AZ6: 2 | BA6: 65 | BB6: =+IF(BA6>0,FIXED(Fuelbeds_english!BB6*2.54,1,0),BA6) -> 1.3 | BC6: -1 | BD6: -1 | BE6: -1 | BF6: -1 | BG6: -1 | BH6: -1 | BI6: 100 | BJ6: -1 | BK6: -1 | BL6: =+IF(BK6>0,FIXED(Fuelbeds_english!BL6*2.54,1,0),BK6) -> -1 | BM6: -1 | BN6: -1 | BO6: =+IF(BN6>0,FIXED(Fuelbeds_english!BO6*2.54,1,0),BN6) -> -1
A7: 6 | B7: 1017 | C7: 1017 | D7: 1 - Trop/Sub Moist Broadleaf Forest | E7: 17 - Crops: tubers | F7: -3 | G7: -3 | H7: =+IF(F7>0,INT(Fuelbeds_english!H7*2.471),F7) -> -3 | I7: =+IF(F7>0,INT(Fuelbeds_english!I7*0.3048),F7) -> -3 | J7: =+IF(F7>0,INT(Fuelbeds_english!J7*0.3048),F7) -> -3 | K7: =+IF(F7>0,INT(Fuelbeds_english!K7*2.54),F7) -> -3 | L7: -3 | M7: -3 | N7: -3 | O7: -3 | P7: =+IF(O7>0,INT(Fuelbeds_english!P7*2.471),O7) -> -3 | Q7: =+IF(O7>0,INT(Fuelbeds_english!Q7*0.3048),O7) -> -3 | R7: =+IF(O7>0,INT(Fuelbeds_english!R7*0.3048),O7) -> -3 | S7: =+IF(O7>0,INT(Fuelbeds_english!S7*2.54),O7) -> -3 | T7: -3 | U7: -3 | V7: -3 | W7: -3 | X7: -3 | Y7: -3 | Z7: =+IF(Y7>0,FIXED(Fuelbeds_english!Z7*0.3048,1,0),Y7) -> -3 | AA7: -3 | AB7: -3 | AC7: -3 | AD7: -3 | AE7: 75 | AF7: =+IF(AE7>0,FIXED(Fuelbeds_english!AF7*0.3048,1,0),AE7) -> 0.0 | AG7: 0 | AH7: =+IF(AE7>0,FIXED(Fuelbeds_english!AH7*2.242,1,0),AE7) -> 0.0 | AI7: 505272 | AJ7: Solanum tuberosum | AK7: 100 | AL7: -3 | AM7: =+IF(AL7>0,FIXED(Fuelbeds_english!AM7*2.54,1,0),AL7) -> -3 | AN7: =+IF(AM7>0,FIXED(Fuelbeds_english!AN7*0.3048,1,0),AM7) -> -3 | AO7: =+IF(AN7>0,FIXED(Fuelbeds_english!AO7*0.3048,1,0),AN7) -> -3 | AP7: =+IF(AO7>0,FIXED(Fuelbeds_english!AP7*0.3048,1,0),AO7) -> -3 | AQ7: =+IF(AP7>0,FIXED(Fuelbeds_english!AQ7*0.3048,1,0),AP7) -> -3 | AR7: -3 | AS7: -3 | AT7: -3 | AU7: -1 | AV7: =+IF(AU7>0,FIXED(Fuelbeds_english!AV7*2.54,1,0),AU7) -> -1 | AW7: -1 | AX7: -1 | AY7: =+IF(AX7>0,FIXED(Fuelbeds_english!AY7*2.54,1,0),AX7) -> -1 | AZ7: 2 | BA7: 65 | BB7: =+IF(BA7>0,FIXED(Fuelbeds_english!BB7*2.54,1,0),BA7) -> 1.3 | BC7: -1 | BD7: -1 | BE7: -1 | BF7: -1 | BG7: -1 | BH7: -1 | BI7: 100 | BJ7: -1 | BK7: -1 | BL7: =+IF(BK7>0,FIXED(Fuelbeds_english!BL7*2.54,1,0),BK7) -> -1 | BM7: -1 | BN7: -1 | BO7: =+IF(BN7>0,FIXED(Fuelbeds_english!BO7*2.54,1,0),BN7) -> -1
A8: 7 | B8: 1018 | C8: 1018 | D8: 1 - Trop/Sub Moist Broadleaf Forest | E8: 18 - Crops: forage | F8: -3 | G8: -3 | H8: =+IF(F8>0,INT(Fuelbeds_english!H8*2.471),F8) -> -3 | I8: =+IF(F8>0,INT(Fuelbeds_english!I8*0.3048),F8) -> -3 | J8: =+IF(F8>0,INT(Fuelbeds_english!J8*0.3048),F8) -> -3 | K8: =+IF(F8>0,INT(Fuelbeds_english!K8*2.54),F8) -> -3 | L8: -3 | M8: -3 | N8: -3 | O8: -3 | P8: =+IF(O8>0,INT(Fuelbeds_english!P8*2.471),O8) -> -3 | Q8: =+IF(O8>0,INT(Fuelbeds_english!Q8*0.3048),O8) -> -3 | R8: =+IF(O8>0,INT(Fuelbeds_english!R8*0.3048),O8) -> -3 | S8: =+IF(O8>0,INT(Fuelbeds_english!S8*2.54),O8) -> -3 | T8: -3 | U8: -3 | V8: -3 | W8: -3 | X8: -3 | Y8: -3 | Z8: =+IF(Y8>0,FIXED(Fuelbeds_english!Z8*0.3048,1,0),Y8) -> -3 | AA8: -3 | AB8: -3 | AC8: -3 | AD8: -3 | AE8: 100 | AF8: =+IF(AE8>0,FIXED(Fuelbeds_english!AF8*0.3048,1,0),AE8) -> 0.2 | AG8: 0 | AH8: =+IF(AE8>0,FIXED(Fuelbeds_english!AH8*2.242,1,0),AE8) -> 2.7 | AI8: 41088 | AJ8: Poa pratensis | AK8: 100 | AL8: -3 | AM8: =+IF(AL8>0,FIXED(Fuelbeds_english!AM8*2.54,1,0),AL8) -> -3 | AN8: =+IF(AM8>0,FIXED(Fuelbeds_english!AN8*0.3048,1,0),AM8) -> -3 | AO8: =+IF(AN8>0,FIXED(Fuelbeds_english!AO8*0.3048,1,0),AN8) -> -3 | AP8: =+IF(AO8>0,FIXED(Fuelbeds_english!AP8*0.3048,1,0),AO8) -> -3 | AQ8: =+IF(AP8>0,FIXED(Fuelbeds_english!AQ8*0.3048,1,0),AP8) -> -3 | AR8: -3 | AS8: -3 | AT8: -3 | AU8: -1 | AV8: =+IF(AU8>0,FIXED(Fuelbeds_english!AV8*2.54,1,0),AU8) -> -1 | AW8: -1 | AX8: -1 | AY8: =+IF(AX8>0,FIXED(Fuelbeds_english!AY8*2.54,1,0),AX8) -> -1 | AZ8: 2 | BA8: 65 | BB8: =+IF(BA8>0,FIXED(Fuelbeds_english!BB8*2.54,1,0),BA8) -> 1.3 | BC8: -1 | BD8: -1 | BE8: -1 | BF8: -1 | BG8: -1 | BH8: -1 | BI8: 100 | BJ8: -1 | BK8: -1 | BL8: =+IF(BK8>0,FIXED(Fuelbeds_english!BL8*2.54,1,0),BK8) -> -1 | BM8: -1 | BN8: -1 | BO8: =+IF(BN8>0,FIXED(Fuelbeds_english!BO8*2.54,1,0),BN8) -> -1
A9: 8 | B9: 1019 | C9: 1019 | D9: 1 - Trop/Sub Moist Broadleaf Forest | E9: 19 - Crops: sugarcane | F9: -3 | G9: -3 | H9: =+IF(F9>0,INT(Fuelbeds_english!H9*2.471),F9) -> -3 | I9: =+IF(F9>0,INT(Fuelbeds_english!I9*0.3048),F9) -> -3 | J9: =+IF(F9>0,INT(Fuelbeds_english!J9*0.3048),F9) -> -3 | K9: =+IF(F9>0,INT(Fuelbeds_english!K9*2.54),F9) -> -3 | L9: -3 | M9: -3 | N9: -3 | O9: -3 | P9: =+IF(O9>0,INT(Fuelbeds_english!P9*2.471),O9) -> -3 | Q9: =+IF(O9>0,INT(Fuelbeds_english!Q9*0.3048),O9) -> -3 | R9: =+IF(O9>0,INT(Fuelbeds_english!R9*0.3048),O9) -> -3 | S9: =+IF(O9>0,INT(Fuelbeds_english!S9*2.54),O9) -> -3 | T9: -3 | U9: -3 | V9: -3 | W9: -3 | X9: -3 | Y9: -3 | Z9: =+IF(Y9>0,FIXED(Fuelbeds_english!Z9*0.3048,1,0),Y9) -> -3 | AA9: -3 | AB9: -3 | AC9: -3 | AD9: -3 | AE9: 100 | AF9: =+IF(AE9>0,FIXED(Fuelbeds_english!AF9*0.3048,1,0),AE9) -> 3.0 | AG9: 100 | AH9: =+IF(AE9>0,FIXED(Fuelbeds_english!AH9*2.242,1,0),AE9) -> 9.1 | AI9: 42058 | AJ9: Saccharum officinarum | AK9: 100 | AL9: -3 | AM9: =+IF(AL9>0,FIXED(Fuelbeds_english!AM9*2.54,1,0),AL9) -> -3 | AN9: =+IF(AM9>0,FIXED(Fuelbeds_english!AN9*0.3048,1,0),AM9) -> -3 | AO9: =+IF(AN9>0,FIXED(Fuelbeds_english!AO9*0.3048,1,0),AN9) -> -3 | AP9: =+IF(AO9>0,FIXED(Fuelbeds_english!AP9*0.3048,1,0),AO9) -> -3 | AQ9: =+IF(AP9>0,FIXED(Fuelbeds_english!AQ9*0.3048,1,0),AP9) -> -3 | AR9: -3 | AS9: -3 | AT9: -3 | AU9: -1 | AV9: =+IF(AU9>0,FIXED(Fuelbeds_english!AV9*2.54,1,0),AU9) -> -1 | AW9: -1 | AX9: -1 | AY9: =+IF(AX9>0,FIXED(Fuelbeds_english!AY9*2.54,1,0),AX9) -> -1 | AZ9: 2 | BA9: 65 | BB9: =+IF(BA9>0,FIXED(Fuelbeds_english!BB9*2.54,1,0),BA9) -> 1.3 | BC9: -1 | BD9: -1 | BE9: -1 | BF9: -1 | BG9: -1 | BH9: -1 | BI9: 100 | BJ9: -1 | BK9: -1 | BL9: =+IF(BK9>0,FIXED(Fuelbeds_english!BL9*2.54,1,0),BK9) -> -1 | BM9: -1 | BN9: -1 | BO9: =+IF(BN9>0,FIXED(Fuelbeds_english!BO9*2.54,1,0),BN9) -> -1
A10: 9 | B10: 1020 | C10: 1020 | D10: 1 - Trop/Sub Moist Broadleaf Forest | E10: 20 - Mosaic Crops/Vegetation: wheat | F10: 32 | G10: 17 | H10: =+IF(F10>0,INT(Fuelbeds_english!H10*2.471),F10) -> 19 | I10: =+IF(F10>0,INT(Fuelbeds_english!I10*0.3048),F10) -> 20 | J10: =+IF(F10>0,INT(Fuelbeds_english!J10*0.3048),F10) -> 10 | K10: =+IF(F10>0,INT(Fuelbeds_english!K10*2.54),F10) -> 30 | L10: 29027 | M10: Swietenia macrophylla | N10: 100 | O10: 32 | P10: =+IF(O10>0,INT(Fuelbeds_english!P10*2.471),O10) -> 123 | Q10: =+IF(O10>0,INT(Fuelbeds_english!Q10*0.3048),O10) -> 10 | R10: =+IF(O10>0,INT(Fuelbeds_english!R10*0.3048),O10) -> 3 | S10: =+IF(O10>0,INT(Fuelbeds_english!S10*2.54),O10) -> 12 | T10: 29027 | U10: Swietenia macrophylla | V10: 100 | W10: 1 | X10: 5 | Y10: 28 | Z10: =+IF(Y10>0,FIXED(Fuelbeds_english!Z10*0.3048,1,0),Y10) -> 1.6 | AA10: 85 | AB10: 19092 | AC10: Ficus aurea | AD10: 100 | AE10: 60 | AF10: =+IF(AE10>0,FIXED(Fuelbeds_english!AF10*0.3048,1,0),AE10) -> 0.2 | AG10: 0 | AH10: =+IF(AE10>0,FIXED(Fuelbeds_english!AH10*2.242,1,0),AE10) -> 0.2 | AI10: 42236 | AJ10: Triticum spp. | AK10: 100 | AL10: 22 | AM10: =+IF(AL10>0,FIXED(Fuelbeds_english!AM10*2.54,1,0),AL10) -> 3.6 | AN10: =+IF($AM10>0,FIXED(Fuelbeds_english!AN10*2.242,1,0),$AM10) -> 0.3 | AO10: =+IF($AM10>0,FIXED(Fuelbeds_english!AO10*2.242,1,0),$AM10) -> 0.9 | AP10: =+IF($AM10>0,FIXED(Fuelbeds_english!AP10*2.242,1,0),$AM10) -> 1.1 | AQ10: =+IF($AM10>0,FIXED(Fuelbeds_english!AQ10*2.242,1,0),$AM10) -> 3.4 | AR10: 29027 | AS10: Swietenia macrophylla | AT10: 100 | AU10: -1 | AV10: =+IF(AU10>0,FIXED(Fuelbeds_english!AV10*2.54,1,0),AU10) -> -1 | AW10: -1 | AX10: -1 | AY10: =+IF(AX10>0,FIXED(Fuelbeds_english!AY10*2.54,1,0),AX10) -> -1 | AZ10: 2 | BA10: 41 | BB10: =+IF(BA10>0,FIXED(Fuelbeds_english!BB10*2.54,1,0),BA10) -> 2.8 | BC10: -1 | BD10: -1 | BE10: -1 | BF10: -1 | BG10: 100 | BH10: -1 | BI10: -1 | BJ10: 1 | BK10: 41 | BL10: =+IF(BK10>0,FIXED(Fuelbeds_english!BL10*2.54,1,0),BK10) -> 1.8 | BM10: 3 | BN10: 41 | BO10: =+IF(BN10>0,FIXED(Fuelbeds_english!BO10*2.54,1,0),BN10) -> 1.8
A11: 10 | B11: 1021 | C11: 1021 | D11: 1 - Trop/Sub Moist Broadleaf Forest | E11: 21 - Mosaic Crops/Vegetation: rice | F11: 33 | G11: 17 | H11: =+IF(F11>0,INT(Fuelbeds_english!H11*2.471),F11) -> 19 | I11: =+IF(F11>0,INT(Fuelbeds_english!I11*0.3048),F11) -> 20 | J11: =+IF(F11>0,INT(Fuelbeds_english!J11*0.3048),F11) -> 10 | K11: =+IF(F11>0,INT(Fuelbeds_english!K11*2.54),F11) -> 27 | L11: 29027 | M11: Swietenia macrophylla | N11: 100 | O11: 33 | P11: =+IF(O11>0,INT(Fuelbeds_english!P11*2.471),O11) -> 126 | Q11: =+IF(O11>0,INT(Fuelbeds_english!Q11*0.3048),O11) -> 10 | R11: =+IF(O11>0,INT(Fuelbeds_english!R11*0.3048),O11) -> 3 | S11: =+IF(O11>0,INT(Fuelbeds_english!S11*2.54),O11) -> 12 | T11: 29027 | U11: Swietenia macrophylla | V11: 100 | W11: 1 | X11: 5 | Y11: 27 | Z11: =+IF(Y11>0,FIXED(Fuelbeds_english!Z11*0.3048,1,0),Y11) -> 1.6 | AA11: 85 | AB11: 19092 | AC11: Ficus aurea | AD11: 100 | AE11: 60 | AF11: =+IF(AE11>0,FIXED(Fuelbeds_english!AF11*0.3048,1,0),AE11) -> 0.2 | AG11: 0 | AH11: =+IF(AE11>0,FIXED(Fuelbeds_english!AH11*2.242,1,0),AE11) -> 1.7 | AI11: 41976 | AJ11: Oryza sativa | AK11: 100 | AL11: 22 | AM11: =+IF(AL11>0,FIXED(Fuelbeds_english!AM11*2.54,1,0),AL11) -> 3.6 | AN11: =+IF($AM11>0,FIXED(Fuelbeds_english!AN11*2.242,1,0),$AM11) -> 0.3 | AO11: =+IF($AM11>0,FIXED(Fuelbeds_english!AO11*2.242,1,0),$AM11) -> 1.0 | AP11: =+IF($AM11>0,FIXED(Fuelbeds_english!AP11*2.242,1,0),$AM11) -> 1.2 | AQ11: =+IF($AM11>0,FIXED(Fuelbeds_english!AQ11*2.242,1,0),$AM11) -> 3.5 | AR11: 29027 | AS11: Swietenia macrophylla | AT11: 100 | AU11: -1 | AV11: =+IF(AU11>0,FIXED(Fuelbeds_english!AV11*2.54,1,0),AU11) -> -1 | AW11: -1 | AX11: -1 | AY11: =+IF(AX11>0,FIXED(Fuelbeds_english!AY11*2.54,1,0),AX11) -> -1 | AZ11: 2 | BA11: 42 | BB11: =+IF(BA11>0,FIXED(Fuelbeds_english!BB11*2.54,1,0),BA11) -> 2.8 | BC11: -1 | BD11: -1 | BE11: -1 | BF11: -1 | BG11: 100 | BH11: -1 | BI11: -1 | BJ11: 1 | BK11: 42 | BL11: =+IF(BK11>0,FIXED(Fuelbeds_english!BL11*2.54,1,0),BK11) -> 1.8 | BM11: 3 | BN11: 42 | BO11: =+IF(BN11>0,FIXED(Fuelbeds_english!BO11*2.54,1,0),BN11) -> 1.8
A12: 11 | B12: 1022 | C12: 1022 | D12: 1 - Trop/Sub Moist Broadleaf Forest | E12: 22 - Mosaic Crops/Vegetation: maize | F12: 24 | G12: 13 | H12: =+IF(F12>0,INT(Fuelbeds_english!H12*2.471),F12) -> 14 | I12: =+IF(F12>0,INT(Fuelbeds_english!I12*0.3048),F12) -> 17 | J12: =+IF(F12>0,INT(Fuelbeds_english!J12*0.3048),F12) -> 9 | K12: =+IF(F12>0,INT(Fuelbeds_english!K12*2.54),F12) -> 20 | L12: 29027 | M12: Swietenia macrophylla | N12: 100 | O12: 24 | P12: =+IF(O12>0,INT(Fuelbeds_english!P12*2.471),O12) -> 93 | Q12: =+IF(O12>0,INT(Fuelbeds_english!Q12*0.3048),O12) -> 9 | R12: =+IF(O12>0,INT(Fuelbeds_english!R12*0.3048),O12) -> 3 | S12: =+IF(O12>0,INT(Fuelbeds_english!S12*2.54),O12) -> 10 | T12: 29027 | U12: Swietenia macrophylla | V12: 100 | W12: 1 | X12: 5 | Y12: 31 | Z12: =+IF(Y12>0,FIXED(Fuelbeds_english!Z12*0.3048,1,0),Y12) -> 1.6 | AA12: 85 | AB12: 19092 | AC12: Ficus aurea | AD12: 100 | AE12: 60 | AF12: =+IF(AE12>0,FIXED(Fuelbeds_english!AF12*0.3048,1,0),AE12) -> 0.2 | AG12: 0 | AH12: =+IF(AE12>0,FIXED(Fuelbeds_english!AH12*2.242,1,0),AE12) -> 0.7 | AI12: 42269 | AJ12: Zea mays | AK12: 100 | AL12: 16 | AM12: =+IF(AL12>0,FIXED(Fuelbeds_english!AM12*2.54,1,0),AL12) -> 3.6 | AN12: =+IF($AM12>0,FIXED(Fuelbeds_english!AN12*2.242,1,0),$AM12) -> 0.2 | AO12: =+IF($AM12>0,FIXED(Fuelbeds_english!AO12*2.242,1,0),$AM12) -> 0.7 | AP12: =+IF($AM12>0,FIXED(Fuelbeds_english!AP12*2.242,1,0),$AM12) -> 0.9 | AQ12: =+IF($AM12>0,FIXED(Fuelbeds_english!AQ12*2.242,1,0),$AM12) -> 2.6 | AR12: 29027 | AS12: Swietenia macrophylla | AT12: 100 | AU12: -1 | AV12: =+IF(AU12>0,FIXED(Fuelbeds_english!AV12*2.54,1,0),AU12) -> -1 | AW12: -1 | AX12: -1 | AY12: =+IF(AX12>0,FIXED(Fuelbeds_english!AY12*2.54,1,0),AX12) -> -1 | AZ12: 2 | BA12: 32 | BB12: =+IF(BA12>0,FIXED(Fuelbeds_english!BB12*2.54,1,0),BA12) -> 2.8 | BC12: -1 | BD12: -1 | BE12: -1 | BF12: -1 | BG12: 100 | BH12: -1 | BI12: -1 | BJ12: 1 | BK12: 32 | BL12: =+IF(BK12>0,FIXED(Fuelbeds_english!BL12*2.54,1,0),BK12) -> 1.8 | BM12: 3 | BN12: 32 | BO12: =+IF(BN12>0,FIXED(Fuelbeds_english!BO12*2.54,1,0),BN12) -> 1.8
A13: 12 | B13: 1023 | C13: 1023 | D13: 1 - Trop/Sub Moist Broadleaf Forest | E13: 23 - Mosaic Crops/Vegetation: soybean | F13: 18 | G13: 9 | H13: =+IF(F13>0,INT(Fuelbeds_english!H13*2.471),F13) -> 9 | I13: =+IF(F13>0,INT(Fuelbeds_english!I13*0.3048),F13) -> 14 | J13: =+IF(F13>0,INT(Fuelbeds_english!J13*0.3048),F13) -> 7 | K13: =+IF(F13>0,INT(Fuelbeds_english!K13*2.54),F13) -> 15 | L13: 29027 | M13: Swietenia macrophylla | N13: 100 | O13: 18 | P13: =+IF(O13>0,INT(Fuelbeds_english!P13*2.471),O13) -> 71 | Q13: =+IF(O13>0,INT(Fuelbeds_english!Q13*0.3048),O13) -> 7 | R13: =+IF(O13>0,INT(Fuelbeds_english!R13*0.3048),O13) -> 2 | S13: =+IF(O13>0,INT(Fuelbeds_english!S13*2.54),O13) -> 7 | T13: 29027 | U13: Swietenia macrophylla | V13: 100 | W13: 1 | X13: 5 | Y13: 33 | Z13: =+IF(Y13>0,FIXED(Fuelbeds_english!Z13*0.3048,1,0),Y13) -> 1.6 | AA13: 85 | AB13: 19092 | AC13: Ficus aurea | AD13: 100 | AE13: 60 | AF13: =+IF(AE13>0,FIXED(Fuelbeds_english!AF13*0.3048,1,0),AE13) -> 0.2 | AG13: 0 | AH13: =+IF(AE13>0,FIXED(Fuelbeds_english!AH13*2.242,1,0),AE13) -> 0.2 | AI13: 26716 | AJ13: Glycine max | AK13: 100 | AL13: 12 | AM13: =+IF(AL13>0,FIXED(Fuelbeds_english!AM13*2.54,1,0),AL13) -> 3.6 | AN13: =+IF($AM13>0,FIXED(Fuelbeds_english!AN13*2.242,1,0),$AM13) -> 0.2 | AO13: =+IF($AM13>0,FIXED(Fuelbeds_english!AO13*2.242,1,0),$AM13) -> 0.5 | AP13: =+IF($AM13>0,FIXED(Fuelbeds_english!AP13*2.242,1,0),$AM13) -> 0.7 | AQ13: =+IF($AM13>0,FIXED(Fuelbeds_english!AQ13*2.242,1,0),$AM13) -> 1.9 | AR13: 29027 | AS13: Swietenia macrophylla | AT13: 100 | AU13: -1 | AV13: =+IF(AU13>0,FIXED(Fuelbeds_english!AV13*2.54,1,0),AU13) -> -1 | AW13: -1 | AX13: -1 | AY13: =+IF(AX13>0,FIXED(Fuelbeds_english!AY13*2.54,1,0),AX13) -> -1 | AZ13: 2 | BA13: 24 | BB13: =+IF(BA13>0,FIXED(Fuelbeds_english!BB13*2.54,1,0),BA13) -> 2.8 | BC13: -1 | BD13: -1 | BE13: -1 | BF13: -1 | BG13: 100 | BH13: -1 | BI13: -1 | BJ13: 1 | BK13: 24 | BL13: =+IF(BK13>0,FIXED(Fuelbeds_english!BL13*2.54,1,0),BK13) -> 1.8 | BM13: 3 | BN13: 24 | BO13: =+IF(BN13>0,FIXED(Fuelbeds_english!BO13*2.54,1,0),BN13) -> 1.8
A14: 13 | B14: 1026 | C14: 1026 | D14: 1 - Trop/Sub Moist Broadleaf Forest | E14: 26 - Mosaic Crops/Vegetation: beans | F14: 21 | G14: 11 | H14: =+IF(F14>0,INT(Fuelbeds_english!H14*2.471),F14) -> 12 | I14: =+IF(F14>0,INT(Fuelbeds_english!I14*0.3048),F14) -> 14 | J14: =+IF(F14>0,INT(Fuelbeds_english!J14*0.3048),F14) -> 7 | K14: =+IF(F14>0,INT(Fuelbeds_english!K14*2.54),F14) -> 15 | L14: 29027 | M14: Swietenia macrophylla | N14: 100 | O14: 21 | P14: =+IF(O14>0,INT(Fuelbeds_english!P14*2.471),O14) -> 84 | Q14: =+IF(O14>0,INT(Fuelbeds_english!Q14*0.3048),O14) -> 7 | R14: =+IF(O14>0,INT(Fuelbeds_english!R14*0.3048),O14) -> 2 | S14: =+IF(O14>0,INT(Fuelbeds_english!S14*2.54),O14) -> 7 | T14: 29027 | U14: Swietenia macrophylla | V14: 100 | W14: 1 | X14: 5 | Y14: 32 | Z14: =+IF(Y14>0,FIXED(Fuelbeds_english!Z14*0.3048,1,0),Y14) -> 1.6 | AA14: 85 | AB14: 19092 | AC14: Ficus aurea | AD14: 100 | AE14: 60 | AF14: =+IF(AE14>0,FIXED(Fuelbeds_english!AF14*0.3048,1,0),AE14) -> 0.1 | AG14: 0 | AH14: =+IF(AE14>0,FIXED(Fuelbeds_english!AH14*2.242,1,0),AE14) -> 0.2 | AI14: 26857 | AJ14: Phaseolus vulgaris | AK14: 100 | AL14: 15 | AM14: =+IF(AL14>0,FIXED(Fuelbeds_english!AM14*2.54,1,0),AL14) -> 3.6 | AN14: =+IF($AM14>0,FIXED(Fuelbeds_english!AN14*2.242,1,0),$AM14) -> 0.2 | AO14: =+IF($AM14>0,FIXED(Fuelbeds_english!AO14*2.242,1,0),$AM14) -> 0.6 | AP14: =+IF($AM14>0,FIXED(Fuelbeds_english!AP14*2.242,1,0),$AM14) -> 0.8 | AQ14: =+IF($AM14>0,FIXED(Fuelbeds_english!AQ14*2.242,1,0),$AM14) -> 2.3 | AR14: 29027 | AS14: Swietenia macrophylla | AT14: 100 | AU14: -1 | AV14: =+IF(AU14>0,FIXED(Fuelbeds_english!AV14*2.54,1,0),AU14) -> -1 | AW14: -1 | AX14: -1 | AY14: =+IF(AX14>0,FIXED(Fuelbeds_english!AY14*2.54,1,0),AX14) -> -1 | AZ14: 2 | BA14: 28 | BB14: =+IF(BA14>0,FIXED(Fuelbeds_english!BB14*2.54,1,0),BA14) -> 2.8 | BC14: -1 | BD14: -1 | BE14: -1 | BF14: -1 | BG14: 100 | BH14: -1 | BI14: -1 | BJ14: 1 | BK14: 28 | BL14: =+IF(BK14>0,FIXED(Fuelbeds_english!BL14*2.54,1,0),BK14) -> 1.8 | BM14: 3 | BN14: 28 | BO14: =+IF(BN14>0,FIXED(Fuelbeds_english!BO14*2.54,1,0),BN14) -> 1.8
A15: 14 | B15: 1027 | C15: 1027 | D15: 1 - Trop/Sub Moist Broadleaf Forest | E15: 27 - Mosaic Crops/Vegetation: tubers | F15: 50 | G15: 26 | H15: =+IF(F15>0,INT(Fuelbeds_english!H15*2.471),F15) -> 29 | I15: =+IF(F15>0,INT(Fuelbeds_english!I15*0.3048),F15) -> 30 | J15: =+IF(F15>0,INT(Fuelbeds_english!J15*0.3048),F15) -> 16 | K15: =+IF(F15>0,INT(Fuelbeds_english!K15*2.54),F15) -> 60 | L15: 29027 | M15: Swietenia macrophylla | N15: 100 | O15: 50 | P15: =+IF(O15>0,INT(Fuelbeds_english!P15*2.471),O15) -> 195 | Q15: =+IF(O15>0,INT(Fuelbeds_english!Q15*0.3048),O15) -> 15 | R15: =+IF(O15>0,INT(Fuelbeds_english!R15*0.3048),O15) -> 5 | S15: =+IF(O15>0,INT(Fuelbeds_english!S15*2.54),O15) -> 17 | T15: 29027 | U15: Swietenia macrophylla | V15: 100 | W15: 1 | X15: 5 | Y15: 31 | Z15: =+IF(Y15>0,FIXED(Fuelbeds_english!Z15*0.3048,1,0),Y15) -> 1.6 | AA15: 85 | AB15: 19092 | AC15: Ficus aurea | AD15: 100 | AE15: 50 | AF15: =+IF(AE15>0,FIXED(Fuelbeds_english!AF15*0.3048,1,0),AE15) -> 0.0 | AG15: 0 | AH15: =+IF(AE15>0,FIXED(Fuelbeds_english!AH15*2.242,1,0),AE15) -> 0.0 | AI15: 505272 | AJ15: Solanum tuberosum | AK15: 100 | AL15: 34 | AM15: =+IF(AL15>0,FIXED(Fuelbeds_english!AM15*2.54,1,0),AL15) -> 3.6 | AN15: =+IF($AM15>0,FIXED(Fuelbeds_english!AN15*2.242,1,0),$AM15) -> 0.4 | AO15: =+IF($AM15>0,FIXED(Fuelbeds_english!AO15*2.242,1,0),$AM15) -> 1.5 | AP15: =+IF($AM15>0,FIXED(Fuelbeds_english!AP15*2.242,1,0),$AM15) -> 1.8 | AQ15: =+IF($AM15>0,FIXED(Fuelbeds_english!AQ15*2.242,1,0),$AM15) -> 5.3 | AR15: 29027 | AS15: Swietenia macrophylla | AT15: 100 | AU15: -1 | AV15: =+IF(AU15>0,FIXED(Fuelbeds_english!AV15*2.54,1,0),AU15) -> -1 | AW15: -1 | AX15: -1 | AY15: =+IF(AX15>0,FIXED(Fuelbeds_english!AY15*2.54,1,0),AX15) -> -1 | AZ15: 2 | BA15: 65 | BB15: =+IF(BA15>0,FIXED(Fuelbeds_english!BB15*2.54,1,0),BA15) -> 2.8 | BC15: -1 | BD15: -1 | BE15: -1 | BF15: -1 | BG15: 100 | BH15: -1 | BI15: -1 | BJ15: 1 | BK15: 65 | BL15: =+IF(BK15>0,FIXED(Fuelbeds_english!BL15*2.54,1,0),BK15) -> 1.8 | BM15: 3 | BN15: 65 | BO15: =+IF(BN15>0,FIXED(Fuelbeds_english!BO15*2.54,1,0),BN15) -> 1.8
A16: 15 | B16: 1028 | C16: 1028 | D16: 1 - Trop/Sub Moist Broadleaf Forest | E16: 28 - Mosaic Crops/Vegetation: forage | F16: 26 | G16: 14 | H16: =+IF(F16>0,INT(Fuelbeds_english!H16*2.471),F16) -> 14 | I16: =+IF(F16>0,INT(Fuelbeds_english!I16*0.3048),F16) -> 13 | J16: =+IF(F16>0,INT(Fuelbeds_english!J16*0.3048),F16) -> 7 | K16: =+IF(F16>0,INT(Fuelbeds_english!K16*2.54),F16) -> 12 | L16: 29027 | M16: Swietenia macrophylla | N16: 100 | O16: 26 | P16: =+IF(O16>0,INT(Fuelbeds_english!P16*2.471),O16) -> 101 | Q16: =+IF(O16>0,INT(Fuelbeds_english!Q16*0.3048),O16) -> 7 | R16: =+IF(O16>0,INT(Fuelbeds_english!R16*0.3048),O16) -> 2 | S16: =+IF(O16>0,INT(Fuelbeds_english!S16*2.54),O16) -> 7 | T16: 29027 | U16: Swietenia macrophylla | V16: 100 | W16: 1 | X16: 5 | Y16: 30 | Z16: =+IF(Y16>0,FIXED(Fuelbeds_english!Z16*0.3048,1,0),Y16) -> 1.6 | AA16: 85 | AB16: 19092 | AC16: Ficus aurea | AD16: 100 | AE16: 60 | AF16: =+IF(AE16>0,FIXED(Fuelbeds_english!AF16*0.3048,1,0),AE16) -> 0.2 | AG16: 0 | AH16: =+IF(AE16>0,FIXED(Fuelbeds_english!AH16*2.242,1,0),AE16) -> 0.4 | AI16: 41088 | AJ16: Poa pratensis | AK16: 100 | AL16: 18 | AM16: =+IF(AL16>0,FIXED(Fuelbeds_english!AM16*2.54,1,0),AL16) -> 3.6 | AN16: =+IF($AM16>0,FIXED(Fuelbeds_english!AN16*2.242,1,0),$AM16) -> 0.2 | AO16: =+IF($AM16>0,FIXED(Fuelbeds_english!AO16*2.242,1,0),$AM16) -> 0.8 | AP16: =+IF($AM16>0,FIXED(Fuelbeds_english!AP16*2.242,1,0),$AM16) -> 0.9 | AQ16: =+IF($AM16>0,FIXED(Fuelbeds_english!AQ16*2.242,1,0),$AM16) -> 2.8 | AR16: 29027 | AS16: Swietenia macrophylla | AT16: 100 | AU16: -1 | AV16: =+IF(AU16>0,FIXED(Fuelbeds_english!AV16*2.54,1,0),AU16) -> -1 | AW16: -1 | AX16: -1 | AY16: =+IF(AX16>0,FIXED(Fuelbeds_english!AY16*2.54,1,0),AX16) -> -1 | AZ16: 2 | BA16: 34 | BB16: =+IF(BA16>0,FIXED(Fuelbeds_english!BB16*2.54,1,0),BA16) -> 2.8 | BC16: -1 | BD16: -1 | BE16: -1 | BF16: -1 | BG16: 100 | BH16: -1 | BI16: -1 | BJ16: 1 | BK16: 34 | BL16: =+IF(BK16>0,FIXED(Fuelbeds_english!BL16*2.54,1,0),BK16) -> 1.8 | BM16: 3 | BN16: 34 | BO16: =+IF(BN16>0,FIXED(Fuelbeds_english!BO16*2.54,1,0),BN16) -> 1.8
A17: 16 | B17: 1029 | C17: 1029 | D17: 1 - Trop/Sub Moist Broadleaf Forest | E17: 29 - Mosaic Crops/Vegetation: sugarcane | F17: 30 | G17: 15 | H17: =+IF(F17>0,INT(Fuelbeds_english!H17*2.471),F17) -> 17 | I17: =+IF(F17>0,INT(Fuelbeds_english!I17*0.3048),F17) -> 19 | J17: =+IF(F17>0,INT(Fuelbeds_english!J17*0.3048),F17) -> 10 | K17: =+IF(F17>0,INT(Fuelbeds_english!K17*2.54),F17) -> 27 | L17: 29027 | M17: Swietenia macrophylla | N17: 100 | O17: 30 | P17: =+IF(O17>0,INT(Fuelbeds_english!P17*2.471),O17) -> 116 | Q17: =+IF(O17>0,INT(Fuelbeds_english!Q17*0.3048),O17) -> 10 | R17: =+IF(O17>0,INT(Fuelbeds_english!R17*0.3048),O17) -> 3 | S17: =+IF(O17>0,INT(Fuelbeds_english!S17*2.54),O17) -> 12 | T17: 29027 | U17: Swietenia macrophylla | V17: 100 | W17: 1 | X17: 5 | Y17: 28 | Z17: =+IF(Y17>0,FIXED(Fuelbeds_english!Z17*0.3048,1,0),Y17) -> 1.6 | AA17: 85 | AB17: 19092 | AC17: Ficus aurea | AD17: 100 | AE17: 60 | AF17: =+IF(AE17>0,FIXED(Fuelbeds_english!AF17*0.3048,1,0),AE17) -> 3.0 | AG17: 100 | AH17: =+IF(AE17>0,FIXED(Fuelbeds_english!AH17*2.242,1,0),AE17) -> 5.4 | AI17: 42058 | AJ17: Saccharum officinarum | AK17: 100 | AL17: 20 | AM17: =+IF(AL17>0,FIXED(Fuelbeds_english!AM17*2.54,1,0),AL17) -> 3.6 | AN17: =+IF($AM17>0,FIXED(Fuelbeds_english!AN17*2.242,1,0),$AM17) -> 0.2 | AO17: =+IF($AM17>0,FIXED(Fuelbeds_english!AO17*2.242,1,0),$AM17) -> 0.9 | AP17: =+IF($AM17>0,FIXED(Fuelbeds_english!AP17*2.242,1,0),$AM17) -> 1.1 | AQ17: =+IF($AM17>0,FIXED(Fuelbeds_english!AQ17*2.242,1,0),$AM17) -> 3.1 | AR17: 29027 | AS17: Swietenia macrophylla | AT17: 100 | AU17: -1 | AV17: =+IF(AU17>0,FIXED(Fuelbeds_english!AV17*2.54,1,0),AU17) -> -1 | AW17: -1 | AX17: -1 | AY17: =+IF(AX17>0,FIXED(Fuelbeds_english!AY17*2.54,1,0),AX17) -> -1 | AZ17: 2 | BA17: 39 | BB17: =+IF(BA17>0,FIXED(Fuelbeds_english!BB17*2.54,1,0),BA17) -> 2.8 | BC17: -1 | BD17: -1 | BE17: -1 | BF17: -1 | BG17: 100 | BH17: -1 | BI17: -1 | BJ17: 1 | BK17: 39 | BL17: =+IF(BK17>0,FIXED(Fuelbeds_english!BL17*2.54,1,0),BK17) -> 1.8 | BM17: 3 | BN17: 39 | BO17: =+IF(BN17>0,FIXED(Fuelbeds_english!BO17*2.54,1,0),BN17) -> 1.8
A18: 17 | B18: 1030a | C18: 911030 | D18: 1 - Trop/Sub Moist Broadleaf Forest | E18: 30 - Mosaic Vegetation/Crops: wheat | F18: 15 | G18: 8 | H18: =+IF(F18>0,INT(Fuelbeds_english!H18*2.471),F18) -> 9 | I18: =+IF(F18>0,INT(Fuelbeds_english!I18*0.3048),F18) -> 14 | J18: =+IF(F18>0,INT(Fuelbeds_english!J18*0.3048),F18) -> 7 | K18: =+IF(F18>0,INT(Fuelbeds_english!K18*2.54),F18) -> 15 | L18: 29027 | M18: Swietenia macrophylla | N18: 100 | O18: 15 | P18: =+IF(O18>0,INT(Fuelbeds_english!P18*2.471),O18) -> 56 | Q18: =+IF(O18>0,INT(Fuelbeds_english!Q18*0.3048),O18) -> 7 | R18: =+IF(O18>0,INT(Fuelbeds_english!R18*0.3048),O18) -> 2 | S18: =+IF(O18>0,INT(Fuelbeds_english!S18*2.54),O18) -> 7 | T18: 29027 | U18: Swietenia macrophylla | V18: 100 | W18: 1 | X18: 5 | Y18: 64 | Z18: =+IF(Y18>0,FIXED(Fuelbeds_english!Z18*0.3048,1,0),Y18) -> 1.6 | AA18: 85 | AB18: 19092 | AC18: Ficus aurea | AD18: 100 | AE18: 30 | AF18: =+IF(AE18>0,FIXED(Fuelbeds_english!AF18*0.3048,1,0),AE18) -> 0.2 | AG18: 0 | AH18: =+IF(AE18>0,FIXED(Fuelbeds_english!AH18*2.242,1,0),AE18) -> 0.1 | AI18: 42236 | AJ18: Triticum spp. | AK18: 100 | AL18: 10 | AM18: =+IF(AL18>0,FIXED(Fuelbeds_english!AM18*2.54,1,0),AL18) -> 3.6 | AN18: =+IF($AM18>0,FIXED(Fuelbeds_english!AN18*2.242,1,0),$AM18) -> 0.1 | AO18: =+IF($AM18>0,FIXED(Fuelbeds_english!AO18*2.242,1,0),$AM18) -> 0.4 | AP18: =+IF($AM18>0,FIXED(Fuelbeds_english!AP18*2.242,1,0),$AM18) -> 0.5 | AQ18: =+IF($AM18>0,FIXED(Fuelbeds_english!AQ18*2.242,1,0),$AM18) -> 1.6 | AR18: 29027 | AS18: Swietenia macrophylla | AT18: 100 | AU18: -1 | AV18: =+IF(AU18>0,FIXED(Fuelbeds_english!AV18*2.54,1,0),AU18) -> -1 | AW18: -1 | AX18: -1 | AY18: =+IF(AX18>0,FIXED(Fuelbeds_english!AY18*2.54,1,0),AX18) -> -1 | AZ18: 1 | BA18: 19 | BB18: =+IF(BA18>0,FIXED(Fuelbeds_english!BB18*2.54,1,0),BA18) -> 2.8 | BC18: -1 | BD18: -1 | BE18: -1 | BF18: -1 | BG18: 100 | BH18: -1 | BI18: -1 | BJ18: 1 | BK18: 19 | BL18: =+IF(BK18>0,FIXED(Fuelbeds_english!BL18*2.54,1,0),BK18) -> 1.8 | BM18: 3 | BN18: 19 | BO18: =+IF(BN18>0,FIXED(Fuelbeds_english!BO18*2.54,1,0),BN18) -> 1.8
A19: 18 | B19: 1030b | C19: 921030 | D19: 1 - Trop/Sub Moist Broadleaf Forest | E19: 30 - Mosaic Vegetation/Crops: wheat | F19: 55 | G19: 29 | H19: =+IF(F19>0,INT(Fuelbeds_english!H19*2.471),F19) -> 32 | I19: =+IF(F19>0,INT(Fuelbeds_english!I19*0.3048),F19) -> 24 | J19: =+IF(F19>0,INT(Fuelbeds_english!J19*0.3048),F19) -> 13 | K19: =+IF(F19>0,INT(Fuelbeds_english!K19*2.54),F19) -> 40 | L19: 29027 | M19: Swietenia macrophylla | N19: 100 | O19: 55 | P19: =+IF(O19>0,INT(Fuelbeds_english!P19*2.471),O19) -> 214 | Q19: =+IF(O19>0,INT(Fuelbeds_english!Q19*0.3048),O19) -> 12 | R19: =+IF(O19>0,INT(Fuelbeds_english!R19*0.3048),O19) -> 4 | S19: =+IF(O19>0,INT(Fuelbeds_english!S19*2.54),O19) -> 12 | T19: 29027 | U19: Swietenia macrophylla | V19: 100 | W19: 1 | X19: 5 | Y19: 49 | Z19: =+IF(Y19>0,FIXED(Fuelbeds_english!Z19*0.3048,1,0),Y19) -> 1.6 | AA19: 85 | AB19: 19092 | AC19: Ficus aurea | AD19: 100 | AE19: 30 | AF19: =+IF(AE19>0,FIXED(Fuelbeds_english!AF19*0.3048,1,0),AE19) -> 0.2 | AG19: 0 | AH19: =+IF(AE19>0,FIXED(Fuelbeds_english!AH19*2.242,1,0),AE19) -> 0.1 | AI19: 42236 | AJ19: Triticum spp. | AK19: 100 | AL19: 37 | AM19: =+IF(AL19>0,FIXED(Fuelbeds_english!AM19*2.54,1,0),AL19) -> 3.6 | AN19: =+IF($AM19>0,FIXED(Fuelbeds_english!AN19*2.242,1,0),$AM19) -> 0.4 | AO19: =+IF($AM19>0,FIXED(Fuelbeds_english!AO19*2.242,1,0),$AM19) -> 1.6 | AP19: =+IF($AM19>0,FIXED(Fuelbeds_english!AP19*2.242,1,0),$AM19) -> 2.0 | AQ19: =+IF($AM19>0,FIXED(Fuelbeds_english!AQ19*2.242,1,0),$AM19) -> 5.8 | AR19: 29027 | AS19: Swietenia macrophylla | AT19: 100 | AU19: -1 | AV19: =+IF(AU19>0,FIXED(Fuelbeds_english!AV19*2.54,1,0),AU19) -> -1 | AW19: -1 | AX19: -1 | AY19: =+IF(AX19>0,FIXED(Fuelbeds_english!AY19*2.54,1,0),AX19) -> -1 | AZ19: 1 | BA19: 71 | BB19: =+IF(BA19>0,FIXED(Fuelbeds_english!BB19*2.54,1,0),BA19) -> 2.8 | BC19: -1 | BD19: -1 | BE19: -1 | BF19: -1 | BG19: 100 | BH19: -1 | BI19: -1 | BJ19: 1 | BK19: 71 | BL19: =+IF(BK19>0,FIXED(Fuelbeds_english!BL19*2.54,1,0),BK19) -> 1.8 | BM19: 3 | BN19: 71 | BO19: =+IF(BN19>0,FIXED(Fuelbeds_english!BO19*2.54,1,0),BN19) -> 1.8
A20: 19 | B20: 1030c | C20: 931030 | D20: 1 - Trop/Sub Moist Broadleaf Forest | E20: 30 - Mosaic Vegetation/Crops: wheat | F20: 77 | G20: 40 | H20: =+IF(F20>0,INT(Fuelbeds_english!H20*2.471),F20) -> 46 | I20: =+IF(F20>0,INT(Fuelbeds_english!I20*0.3048),F20) -> 31 | J20: =+IF(F20>0,INT(Fuelbeds_english!J20*0.3048),F20) -> 16 | K20: =+IF(F20>0,INT(Fuelbeds_english!K20*2.54),F20) -> 66 | L20: 29027 | M20: Swietenia macrophylla | N20: 100 | O20: 77 | P20: =+IF(O20>0,INT(Fuelbeds_english!P20*2.471),O20) -> 301 | Q20: =+IF(O20>0,INT(Fuelbeds_english!Q20*0.3048),O20) -> 16 | R20: =+IF(O20>0,INT(Fuelbeds_english!R20*0.3048),O20) -> 5 | S20: =+IF(O20>0,INT(Fuelbeds_english!S20*2.54),O20) -> 20 | T20: 29027 | U20: Swietenia macrophylla | V20: 100 | W20: 1 | X20: 5 | Y20: 47 | Z20: =+IF(Y20>0,FIXED(Fuelbeds_english!Z20*0.3048,1,0),Y20) -> 1.6 | AA20: 85 | AB20: 19092 | AC20: Ficus aurea | AD20: 100 | AE20: 22.8 | AF20: =+IF(AE20>0,FIXED(Fuelbeds_english!AF20*0.3048,1,0),AE20) -> 0.2 | AG20: 0 | AH20: =+IF(AE20>0,FIXED(Fuelbeds_english!AH20*2.242,1,0),AE20) -> 0.1 | AI20: 42236 | AJ20: Triticum spp. | AK20: 100 | AL20: 52 | AM20: =+IF(AL20>0,FIXED(Fuelbeds_english!AM20*2.54,1,0),AL20) -> 3.6 | AN20: =+IF($AM20>0,FIXED(Fuelbeds_english!AN20*2.242,1,0),$AM20) -> 0.6 | AO20: =+IF($AM20>0,FIXED(Fuelbeds_english!AO20*2.242,1,0),$AM20) -> 2.3 | AP20: =+IF($AM20>0,FIXED(Fuelbeds_english!AP20*2.242,1,0),$AM20) -> 2.8 | AQ20: =+IF($AM20>0,FIXED(Fuelbeds_english!AQ20*2.242,1,0),$AM20) -> 8.2 | AR20: 29027 | AS20: Swietenia macrophylla | AT20: 100 | AU20: -1 | AV20: =+IF(AU20>0,FIXED(Fuelbeds_english!AV20*2.54,1,0),AU20) -> -1 | AW20: -1 | AX20: -1 | AY20: =+IF(AX20>0,FIXED(Fuelbeds_english!AY20*2.54,1,0),AX20) -> -1 | AZ20: 1 | BA20: 100 | BB20: =+IF(BA20>0,FIXED(Fuelbeds_english!BB20*2.54,1,0),BA20) -> 2.8 | BC20: -1 | BD20: -1 | BE20: -1 | BF20: -1 | BG20: 100 | BH20: -1 | BI20: -1 | BJ20: 1 | BK20: 100 | BL20: =+IF(BK20>0,FIXED(Fuelbeds_english!BL20*2.54,1,0),BK20) -> 1.8 | BM20: 3 | BN20: 100 | BO20: =+IF(BN20>0,FIXED(Fuelbeds_english!BO20*2.54,1,0),BN20) -> 1.8
A21: 20 | B21: 1031a | C21: 911031 | D21: 1 - Trop/Sub Moist Broadleaf Forest | E21: 31 - Mosaic Vegetation/Crops: rice | F21: 21 | G21: 11 | H21: =+IF(F21>0,INT(Fuelbeds_english!H21*2.471),F21) -> 12 | I21: =+IF(F21>0,INT(Fuelbeds_english!I21*0.3048),F21) -> 17 | J21: =+IF(F21>0,INT(Fuelbeds_english!J21*0.3048),F21) -> 9 | K21: =+IF(F21>0,INT(Fuelbeds_english!K21*2.54),F21) -> 22 | L21: 29027 | M21: Swietenia macrophylla | N21: 100 | O21: 21 | P21: =+IF(O21>0,INT(Fuelbeds_english!P21*2.471),O21) -> 79 | Q21: =+IF(O21>0,INT(Fuelbeds_english!Q21*0.3048),O21) -> 9 | R21: =+IF(O21>0,INT(Fuelbeds_english!R21*0.3048),O21) -> 3 | S21: =+IF(O21>0,INT(Fuelbeds_english!S21*2.54),O21) -> 10 | T21: 29027 | U21: Swietenia macrophylla | V21: 100 | W21: 1 | X21: 5 | Y21: 62 | Z21: =+IF(Y21>0,FIXED(Fuelbeds_english!Z21*0.3048,1,0),Y21) -> 1.6 | AA21: 85 | AB21: 19092 | AC21: Ficus aurea | AD21: 100 | AE21: 30 | AF21: =+IF(AE21>0,FIXED(Fuelbeds_english!AF21*0.3048,1,0),AE21) -> 0.2 | AG21: 0 | AH21: =+IF(AE21>0,FIXED(Fuelbeds_english!AH21*2.242,1,0),AE21) -> 0.9 | AI21: 41976 | AJ21: Oryza sativa | AK21: 100 | AL21: 14 | AM21: =+IF(AL21>0,FIXED(Fuelbeds_english!AM21*2.54,1,0),AL21) -> 3.6 | AN21: =+IF($AM21>0,FIXED(Fuelbeds_english!AN21*2.242,1,0),$AM21) -> 0.2 | AO21: =+IF($AM21>0,FIXED(Fuelbeds_english!AO21*2.242,1,0),$AM21) -> 0.6 | AP21: =+IF($AM21>0,FIXED(Fuelbeds_english!AP21*2.242,1,0),$AM21) -> 0.7 | AQ21: =+IF($AM21>0,FIXED(Fuelbeds_english!AQ21*2.242,1,0),$AM21) -> 2.2 | AR21: 29027 | AS21: Swietenia macrophylla | AT21: 100 | AU21: -1 | AV21: =+IF(AU21>0,FIXED(Fuelbeds_english!AV21*2.54,1,0),AU21) -> -1 | AW21: -1 | AX21: -1 | AY21: =+IF(AX21>0,FIXED(Fuelbeds_english!AY21*2.54,1,0),AX21) -> -1 | AZ21: 1 | BA21: 27 | BB21: =+IF(BA21>0,FIXED(Fuelbeds_english!BB21*2.54,1,0),BA21) -> 2.8 | BC21: -1 | BD21: -1 | BE21: -1 | BF21: -1 | BG21: 100 | BH21: -1 | BI21: -1 | BJ21: 1 | BK21: 27 | BL21: =+IF(BK21>0,FIXED(Fuelbeds_english!BL21*2.54,1,0),BK21) -> 1.8 | BM21: 3 | BN21: 27 | BO21: =+IF(BN21>0,FIXED(Fuelbeds_english!BO21*2.54,1,0),BN21) -> 1.8
A22: 21 | B22: 1031b | C22: 921031 | D22: 1 - Trop/Sub Moist Broadleaf Forest | E22: 31 - Mosaic Vegetation/Crops: rice | F22: 53 | G22: 28 | H22: =+IF(F22>0,INT(Fuelbeds_english!H22*2.471),F22) -> 32 | I22: =+IF(F22>0,INT(Fuelbeds_english!I22*0.3048),F22) -> 23 | J22: =+IF(F22>0,INT(Fuelbeds_english!J22*0.3048),F22) -> 12 | K22: =+IF(F22>0,INT(Fuelbeds_english!K22*2.54),F22) -> 38 | L22: 29027 | M22: Swietenia macrophylla | N22: 100 | O22: 53 | P22: =+IF(O22>0,INT(Fuelbeds_english!P22*2.471),O22) -> 207 | Q22: =+IF(O22>0,INT(Fuelbeds_english!Q22*0.3048),O22) -> 12 | R22: =+IF(O22>0,INT(Fuelbeds_english!R22*0.3048),O22) -> 3 | S22: =+IF(O22>0,INT(Fuelbeds_english!S22*2.54),O22) -> 10 | T22: 29027 | U22: Swietenia macrophylla | V22: 100 | W22: 1 | X22: 5 | Y22: 49 | Z22: =+IF(Y22>0,FIXED(Fuelbeds_english!Z22*0.3048,1,0),Y22) -> 1.6 | AA22: 85 | AB22: 19092 | AC22: Ficus aurea | AD22: 100 | AE22: 30 | AF22: =+IF(AE22>0,FIXED(Fuelbeds_english!AF22*0.3048,1,0),AE22) -> 0.2 | AG22: 0 | AH22: =+IF(AE22>0,FIXED(Fuelbeds_english!AH22*2.242,1,0),AE22) -> 0.9 | AI22: 41976 | AJ22: Oryza sativa | AK22: 100 | AL22: 36 | AM22: =+IF(AL22>0,FIXED(Fuelbeds_english!AM22*2.54,1,0),AL22) -> 3.6 | AN22: =+IF($AM22>0,FIXED(Fuelbeds_english!AN22*2.242,1,0),$AM22) -> 0.4 | AO22: =+IF($AM22>0,FIXED(Fuelbeds_english!AO22*2.242,1,0),$AM22) -> 1.6 | AP22: =+IF($AM22>0,FIXED(Fuelbeds_english!AP22*2.242,1,0),$AM22) -> 1.9 | AQ22: =+IF($AM22>0,FIXED(Fuelbeds_english!AQ22*2.242,1,0),$AM22) -> 5.6 | AR22: 29027 | AS22: Swietenia macrophylla | AT22: 100 | AU22: -1 | AV22: =+IF(AU22>0,FIXED(Fuelbeds_english!AV22*2.54,1,0),AU22) -> -1 | AW22: -1 | AX22: -1 | AY22: =+IF(AX22>0,FIXED(Fuelbeds_english!AY22*2.54,1,0),AX22) -> -1 | AZ22: 1 | BA22: 69 | BB22: =+IF(BA22>0,FIXED(Fuelbeds_english!BB22*2.54,1,0),BA22) -> 2.8 | BC22: -1 | BD22: -1 | BE22: -1 | BF22: -1 | BG22: 100 | BH22: -1 | BI22: -1 | BJ22: 1 | BK22: 69 | BL22: =+IF(BK22>0,FIXED(Fuelbeds_english!BL22*2.54,1,0),BK22) -> 1.8 | BM22: 3 | BN22: 69 | BO22: =+IF(BN22>0,FIXED(Fuelbeds_english!BO22*2.54,1,0),BN22) -> 1.8
A23: 22 | B23: 1031c | C23: 931031 | D23: 1 - Trop/Sub Moist Broadleaf Forest | E23: 31 - Mosaic Vegetation/Crops: rice | F23: 77 | G23: 40 | H23: =+IF(F23>0,INT(Fuelbeds_english!H23*2.471),F23) -> 46 | I23: =+IF(F23>0,INT(Fuelbeds_english!I23*0.3048),F23) -> 29 | J23: =+IF(F23>0,INT(Fuelbeds_english!J23*0.3048),F23) -> 15 | K23: =+IF(F23>0,INT(Fuelbeds_english!K23*2.54),F23) -> 58 | L23: 29027 | M23: Swietenia macrophylla | N23: 100 | O23: 77 | P23: =+IF(O23>0,INT(Fuelbeds_english!P23*2.471),O23) -> 298 | Q23: =+IF(O23>0,INT(Fuelbeds_english!Q23*0.3048),O23) -> 15 | R23: =+IF(O23>0,INT(Fuelbeds_english!R23*0.3048),O23) -> 4 | S23: =+IF(O23>0,INT(Fuelbeds_english!S23*2.54),O23) -> 17 | T23: 29027 | U23: Swietenia macrophylla | V23: 100 | W23: 1 | X23: 5 | Y23: 47 | Z23: =+IF(Y23>0,FIXED(Fuelbeds_english!Z23*0.3048,1,0),Y23) -> 1.6 | AA23: 85 | AB23: 19092 | AC23: Ficus aurea | AD23: 100 | AE23: 23.3 | AF23: =+IF(AE23>0,FIXED(Fuelbeds_english!AF23*0.3048,1,0),AE23) -> 0.2 | AG23: 0 | AH23: =+IF(AE23>0,FIXED(Fuelbeds_english!AH23*2.242,1,0),AE23) -> 0.7 | AI23: 41976 | AJ23: Oryza sativa | AK23: 100 | AL23: 52 | AM23: =+IF(AL23>0,FIXED(Fuelbeds_english!AM23*2.54,1,0),AL23) -> 3.6 | AN23: =+IF($AM23>0,FIXED(Fuelbeds_english!AN23*2.242,1,0),$AM23) -> 0.6 | AO23: =+IF($AM23>0,FIXED(Fuelbeds_english!AO23*2.242,1,0),$AM23) -> 2.2 | AP23: =+IF($AM23>0,FIXED(Fuelbeds_english!AP23*2.242,1,0),$AM23) -> 2.8 | AQ23: =+IF($AM23>0,FIXED(Fuelbeds_english!AQ23*2.242,1,0),$AM23) -> 8.1 | AR23: 29027 | AS23: Swietenia macrophylla | AT23: 100 | AU23: -1 | AV23: =+IF(AU23>0,FIXED(Fuelbeds_english!AV23*2.54,1,0),AU23) -> -1 | AW23: -1 | AX23: -1 | AY23: =+IF(AX23>0,FIXED(Fuelbeds_english!AY23*2.54,1,0),AX23) -> -1 | AZ23: 1 | BA23: 100 | BB23: =+IF(BA23>0,FIXED(Fuelbeds_english!BB23*2.54,1,0),BA23) -> 2.8 | BC23: -1 | BD23: -1 | BE23: -1 | BF23: -1 | BG23: 100 | BH23: -1 | BI23: -1 | BJ23: 1 | BK23: 100 | BL23: =+IF(BK23>0,FIXED(Fuelbeds_english!BL23*2.54,1,0),BK23) -> 1.8 | BM23: 3 | BN23: 100 | BO23: =+IF(BN23>0,FIXED(Fuelbeds_english!BO23*2.54,1,0),BN23) -> 1.8
A24: 23 | B24: 1032a | C24: 911032 | D24: 1 - Trop/Sub Moist Broadleaf Forest | E24: 32 - Mosaic Vegetation/Crops: maize | F24: 16 | G24: 9 | H24: =+IF(F24>0,INT(Fuelbeds_english!H24*2.471),F24) -> 9 | I24: =+IF(F24>0,INT(Fuelbeds_english!I24*0.3048),F24) -> 16 | J24: =+IF(F24>0,INT(Fuelbeds_english!J24*0.3048),F24) -> 8 | K24: =+IF(F24>0,INT(Fuelbeds_english!K24*2.54),F24) -> 20 | L24: 29027 | M24: Swietenia macrophylla | N24: 100 | O24: 16 | P24: =+IF(O24>0,INT(Fuelbeds_english!P24*2.471),O24) -> 64 | Q24: =+IF(O24>0,INT(Fuelbeds_english!Q24*0.3048),O24) -> 8 | R24: =+IF(O24>0,INT(Fuelbeds_english!R24*0.3048),O24) -> 2 | S24: =+IF(O24>0,INT(Fuelbeds_english!S24*2.54),O24) -> 10 | T24: 29027 | U24: Swietenia macrophylla | V24: 100 | W24: 1 | X24: 5 | Y24: 64 | Z24: =+IF(Y24>0,FIXED(Fuelbeds_english!Z24*0.3048,1,0),Y24) -> 1.6 | AA24: 85 | AB24: 19092 | AC24: Ficus aurea | AD24: 100 | AE24: 30 | AF24: =+IF(AE24>0,FIXED(Fuelbeds_english!AF24*0.3048,1,0),AE24) -> 0.2 | AG24: 0 | AH24: =+IF(AE24>0,FIXED(Fuelbeds_english!AH24*2.242,1,0),AE24) -> 0.3 | AI24: 42269 | AJ24: Zea mays | AK24: 100 | AL24: 11 | AM24: =+IF(AL24>0,FIXED(Fuelbeds_english!AM24*2.54,1,0),AL24) -> 3.6 | AN24: =+IF($AM24>0,FIXED(Fuelbeds_english!AN24*2.242,1,0),$AM24) -> 0.1 | AO24: =+IF($AM24>0,FIXED(Fuelbeds_english!AO24*2.242,1,0),$AM24) -> 0.5 | AP24: =+IF($AM24>0,FIXED(Fuelbeds_english!AP24*2.242,1,0),$AM24) -> 0.6 | AQ24: =+IF($AM24>0,FIXED(Fuelbeds_english!AQ24*2.242,1,0),$AM24) -> 1.7 | AR24: 29027 | AS24: Swietenia macrophylla | AT24: 100 | AU24: -1 | AV24: =+IF(AU24>0,FIXED(Fuelbeds_english!AV24*2.54,1,0),AU24) -> -1 | AW24: -1 | AX24: -1 | AY24: =+IF(AX24>0,FIXED(Fuelbeds_english!AY24*2.54,1,0),AX24) -> -1 | AZ24: 1 | BA24: 21 | BB24: =+IF(BA24>0,FIXED(Fuelbeds_english!BB24*2.54,1,0),BA24) -> 2.8 | BC24: -1 | BD24: -1 | BE24: -1 | BF24: -1 | BG24: 100 | BH24: -1 | BI24: -1 | BJ24: 1 | BK24: 21 | BL24: =+IF(BK24>0,FIXED(Fuelbeds_english!BL24*2.54,1,0),BK24) -> 1.8 | BM24: 3 | BN24: 21 | BO24: =+IF(BN24>0,FIXED(Fuelbeds_english!BO24*2.54,1,0),BN24) -> 1.8
A25: 24 | B25: 1032b | C25: 921032 | D25: 1 - Trop/Sub Moist Broadleaf Forest | E25: 32 - Mosaic Vegetation/Crops: maize | F25: 53 | G25: 28 | H25: =+IF(F25>0,INT(Fuelbeds_english!H25*2.471),F25) -> 32 | I25: =+IF(F25>0,INT(Fuelbeds_english!I25*0.3048),F25) -> 22 | J25: =+IF(F25>0,INT(Fuelbeds_english!J25*0.3048),F25) -> 11 | K25: =+IF(F25>0,INT(Fuelbeds_english!K25*2.54),F25) -> 33 | L25: 29027 | M25: Swietenia macrophylla | N25: 100 | O25: 53 | P25: =+IF(O25>0,INT(Fuelbeds_english!P25*2.471),O25) -> 207 | Q25: =+IF(O25>0,INT(Fuelbeds_english!Q25*0.3048),O25) -> 11 | R25: =+IF(O25>0,INT(Fuelbeds_english!R25*0.3048),O25) -> 3 | S25: =+IF(O25>0,INT(Fuelbeds_english!S25*2.54),O25) -> 10 | T25: 29027 | U25: Swietenia macrophylla | V25: 100 | W25: 1 | X25: 5 | Y25: 49 | Z25: =+IF(Y25>0,FIXED(Fuelbeds_english!Z25*0.3048,1,0),Y25) -> 1.6 | AA25: 85 | AB25: 19092 | AC25: Ficus aurea | AD25: 100 | AE25: 30 | AF25: =+IF(AE25>0,FIXED(Fuelbeds_english!AF25*0.3048,1,0),AE25) -> 0.2 | AG25: 0 | AH25: =+IF(AE25>0,FIXED(Fuelbeds_english!AH25*2.242,1,0),AE25) -> 0.3 | AI25: 42269 | AJ25: Zea mays | AK25: 100 | AL25: 36 | AM25: =+IF(AL25>0,FIXED(Fuelbeds_english!AM25*2.54,1,0),AL25) -> 3.6 | AN25: =+IF($AM25>0,FIXED(Fuelbeds_english!AN25*2.242,1,0),$AM25) -> 0.4 | AO25: =+IF($AM25>0,FIXED(Fuelbeds_english!AO25*2.242,1,0),$AM25) -> 1.6 | AP25: =+IF($AM25>0,FIXED(Fuelbeds_english!AP25*2.242,1,0),$AM25) -> 1.9 | AQ25: =+IF($AM25>0,FIXED(Fuelbeds_english!AQ25*2.242,1,0),$AM25) -> 5.6 | AR25: 29027 | AS25: Swietenia macrophylla | AT25: 100 | AU25: -1 | AV25: =+IF(AU25>0,FIXED(Fuelbeds_english!AV25*2.54,1,0),AU25) -> -1 | AW25: -1 | AX25: -1 | AY25: =+IF(AX25>0,FIXED(Fuelbeds_english!AY25*2.54,1,0),AX25) -> -1 | AZ25: 1 | BA25: 69 | BB25: =+IF(BA25>0,FIXED(Fuelbeds_english!BB25*2.54,1,0),BA25) -> 2.8 | BC25: -1 | BD25: -1 | BE25: -1 | BF25: -1 | BG25: 100 | BH25: -1 | BI25: -1 | BJ25: 1 | BK25: 69 | BL25: =+IF(BK25>0,FIXED(Fuelbeds_english!BL25*2.54,1,0),BK25) -> 1.8 | BM25: 3 | BN25: 69 | BO25: =+IF(BN25>0,FIXED(Fuelbeds_english!BO25*2.54,1,0),BN25) -> 1.8
A26: 25 | B26: 1032c | C26: 931032 | D26: 1 - Trop/Sub Moist Broadleaf Forest | E26: 32 - Mosaic Vegetation/Crops: maize | F26: 76 | G26: 40 | H26: =+IF(F26>0,INT(Fuelbeds_english!H26*2.471),F26) -> 46 | I26: =+IF(F26>0,INT(Fuelbeds_english!I26*0.3048),F26) -> 29 | J26: =+IF(F26>0,INT(Fuelbeds_english!J26*0.3048),F26) -> 15 | K26: =+IF(F26>0,INT(Fuelbeds_english!K26*2.54),F26) -> 58 | L26: 29027 | M26: Swietenia macrophylla | N26: 100 | O26: 76 | P26: =+IF(O26>0,INT(Fuelbeds_english!P26*2.471),O26) -> 296 | Q26: =+IF(O26>0,INT(Fuelbeds_english!Q26*0.3048),O26) -> 15 | R26: =+IF(O26>0,INT(Fuelbeds_english!R26*0.3048),O26) -> 5 | S26: =+IF(O26>0,INT(Fuelbeds_english!S26*2.54),O26) -> 17 | T26: 29027 | U26: Swietenia macrophylla | V26: 100 | W26: 1 | X26: 5 | Y26: 46 | Z26: =+IF(Y26>0,FIXED(Fuelbeds_english!Z26*0.3048,1,0),Y26) -> 1.6 | AA26: 85 | AB26: 19092 | AC26: Ficus aurea | AD26: 100 | AE26: 23.9 | AF26: =+IF(AE26>0,FIXED(Fuelbeds_english!AF26*0.3048,1,0),AE26) -> 0.2 | AG26: 0 | AH26: =+IF(AE26>0,FIXED(Fuelbeds_english!AH26*2.242,1,0),AE26) -> 0.2 | AI26: 42269 | AJ26: Zea mays | AK26: 100 | AL26: 51 | AM26: =+IF(AL26>0,FIXED(Fuelbeds_english!AM26*2.54,1,0),AL26) -> 3.6 | AN26: =+IF($AM26>0,FIXED(Fuelbeds_english!AN26*2.242,1,0),$AM26) -> 0.6 | AO26: =+IF($AM26>0,FIXED(Fuelbeds_english!AO26*2.242,1,0),$AM26) -> 2.2 | AP26: =+IF($AM26>0,FIXED(Fuelbeds_english!AP26*2.242,1,0),$AM26) -> 2.7 | AQ26: =+IF($AM26>0,FIXED(Fuelbeds_english!AQ26*2.242,1,0),$AM26) -> 8.1 | AR26: 29027 | AS26: Swietenia macrophylla | AT26: 100 | AU26: -1 | AV26: =+IF(AU26>0,FIXED(Fuelbeds_english!AV26*2.54,1,0),AU26) -> -1 | AW26: -1 | AX26: -1 | AY26: =+IF(AX26>0,FIXED(Fuelbeds_english!AY26*2.54,1,0),AX26) -> -1 | AZ26: 1 | BA26: 99 | BB26: =+IF(BA26>0,FIXED(Fuelbeds_english!BB26*2.54,1,0),BA26) -> 2.8 | BC26: -1 | BD26: -1 | BE26: -1 | BF26: -1 | BG26: 100 | BH26: -1 | BI26: -1 | BJ26: 1 | BK26: 99 | BL26: =+IF(BK26>0,FIXED(Fuelbeds_english!BL26*2.54,1,0),BK26) -> 1.8 | BM26: 3 | BN26: 99 | BO26: =+IF(BN26>0,FIXED(Fuelbeds_english!BO26*2.54,1,0),BN26) -> 1.8
A27: 26 | B27: 1033 | C27: 1033 | D27: 1 - Trop/Sub Moist Broadleaf Forest | E27: 33 - Mosaic Vegetation/Crops: soybean | F27: 14 | G27: 7 | H27: =+IF(F27>0,INT(Fuelbeds_english!H27*2.471),F27) -> 7 | I27: =+IF(F27>0,INT(Fuelbeds_english!I27*0.3048),F27) -> 13 | J27: =+IF(F27>0,INT(Fuelbeds_english!J27*0.3048),F27) -> 7 | K27: =+IF(F27>0,INT(Fuelbeds_english!K27*2.54),F27) -> 12 | L27: 29027 | M27: Swietenia macrophylla | N27: 100 | O27: 14 | P27: =+IF(O27>0,INT(Fuelbeds_english!P27*2.471),O27) -> 54 | Q27: =+IF(O27>0,INT(Fuelbeds_english!Q27*0.3048),O27) -> 7 | R27: =+IF(O27>0,INT(Fuelbeds_english!R27*0.3048),O27) -> 2 | S27: =+IF(O27>0,INT(Fuelbeds_english!S27*2.54),O27) -> 7 | T27: 29027 | U27: Swietenia macrophylla | V27: 100 | W27: 1 | X27: 5 | Y27: 65 | Z27: =+IF(Y27>0,FIXED(Fuelbeds_english!Z27*0.3048,1,0),Y27) -> 1.6 | AA27: 85 | AB27: 19092 | AC27: Ficus aurea | AD27: 100 | AE27: 30 | AF27: =+IF(AE27>0,FIXED(Fuelbeds_english!AF27*0.3048,1,0),AE27) -> 0.2 | AG27: 0 | AH27: =+IF(AE27>0,FIXED(Fuelbeds_english!AH27*2.242,1,0),AE27) -> 0.1 | AI27: 26716 | AJ27: Glycine max | AK27: 100 | AL27: 9 | AM27: =+IF(AL27>0,FIXED(Fuelbeds_english!AM27*2.54,1,0),AL27) -> 3.6 | AN27: =+IF($AM27>0,FIXED(Fuelbeds_english!AN27*2.242,1,0),$AM27) -> 0.1 | AO27: =+IF($AM27>0,FIXED(Fuelbeds_english!AO27*2.242,1,0),$AM27) -> 0.4 | AP27: =+IF($AM27>0,FIXED(Fuelbeds_english!AP27*2.242,1,0),$AM27) -> 0.5 | AQ27: =+IF($AM27>0,FIXED(Fuelbeds_english!AQ27*2.242,1,0),$AM27) -> 1.5 | AR27: 29027 | AS27: Swietenia macrophylla | AT27: 100 | AU27: -1 | AV27: =+IF(AU27>0,FIXED(Fuelbeds_english!AV27*2.54,1,0),AU27) -> -1 | AW27: -1 | AX27: -1 | AY27: =+IF(AX27>0,FIXED(Fuelbeds_english!AY27*2.54,1,0),AX27) -> -1 | AZ27: 1 | BA27: 18 | BB27: =+IF(BA27>0,FIXED(Fuelbeds_english!BB27*2.54,1,0),BA27) -> 2.8 | BC27: -1 | BD27: -1 | BE27: -1 | BF27: -1 | BG27: 100 | BH27: -1 | BI27: -1 | BJ27: 1 | BK27: 18 | BL27: =+IF(BK27>0,FIXED(Fuelbeds_english!BL27*2.54,1,0),BK27) -> 1.8 | BM27: 3 | BN27: 18 | BO27: =+IF(BN27>0,FIXED(Fuelbeds_english!BO27*2.54,1,0),BN27) -> 1.8
